Workbook

Sheet Input
A1: ID | B1: X | C1: Y | D1: Z | E1: INFLOW | F1: v1 | G1: v2 | H1: slope | I1: intercept
A2: 1 | B2: 2 | C2: 1 | D2: 2.5 | E2: 0.005 | F2: 4 | G2: 3 | H2: 0.003 | I2: 1 | O2: 1 | P2: 1 | Q2: 2
A3: 2 | B3: 4 | C3: 1 | D3: 2.6 | E3: 0.006 | F3: 1 | G3: 2 | H3: 0.003 | I3: 1 | O3: 2 | P3: 1 | Q3: 4
A4: 3 | B4: 5.7 | C4: 1 | D4: 2.7 | E4: 0.005 | F4: 2 | G4: 55 | H4: 0.0038 | I4: 1 | O4: 3 | P4: 1 | Q4: 5.7
A5: 4 | B5: 7 | C5: 1 | D5: 2.8 | E5: 0.003 | F5: 1 | G5: 7 | H5: 0.003 | I5: 1 | O5: 4 | P5: 1 | Q5: 7
A6: 5 | B6: 2.5 | C6: 2 | D6: 2.6 | E6: 0.007 | F6: 19 | G6: 18 | H6: 0.003 | I6: 1 | O6: 5 | P6: 2 | Q6: 2.5
A7: 6 | B7: 5 | C7: 2 | D7: 2.6 | E7: 0.01 | F7: 5 | G7: 8 | H7: 0.003 | I7: 1 | O7: 6 | P7: 2 | Q7: 5
A8: 7 | B8: 1 | C8: 3 | D8: 2.3 | E8: 0.009 | F8: 6 | G8: 11 | H8: 0.0027 | I8: 1 | O8: 7 | P8: 3 | Q8: 1
A9: 8 | B9: 2 | C9: 3 | D9: 2.5 | E9: 0.01 | F9: 7 | G9: 8 | H9: 0.003 | I9: 1 | O9: 8 | P9: 3 | Q9: 2
A10: 9 | B10: 3 | C10: 3 | D10: 2.9 | E10: 0.003 | F10: 8 | G10: 9 | H10: 0.0024 | I10: 1 | O10: 9 | P10: 3 | Q10: 3
A11: 10 | B11: 4 | C11: 3 | D11: 2.85 | E11: 0.01 | F11: 9 | G11: 15 | H11: 0.002 | I11: 1 | O11: 10 | P11: 3 | Q11: 4
A12: 11 | B12: 5 | C12: 3 | D12: 2.8 | E12: 0.017 | F12: 10 | G12: 11 | H12: 0.003 | I12: 1 | O12: 11 | P12: 3 | Q12: 5
A13: 12 | B13: 6 | C13: 3 | D13: 2.8 | E13: 0.004 | F13: 10 | G13: 55 | H13: 0.003 | I13: 1 | O13: 12 | P13: 3 | Q13: 6
... A58: 57 | B58: 7 | C58: 13 | D58: 2.2 | E58: -0.34 | F58: 41 | G58: 42 | H58: 0.0013 | I58: 1 | O58: 57 | P58: 13 | Q58: 7
F59: 43 | G59: 44 | H59: 0.003 | I59: 1
F60: 42 | G60: 43 | H60: 0.0012 | I60: 1
F61: 43 | G61: 49 | H61: 0.0015 | I61: 1
F62: 23 | G62: 24 | H62: 0.003 | I62: 1
F63: 24 | G63: 36 | H63: 0.003 | I63: 1
F64: 45 | G64: 51 | H64: 0.003 | I64: 1
F65: 48 | G65: 47 | H65: 0.003 | I65: 1
F66: 47 | G66: 52 | H66: 0.004 | I66: 1
F67: 46 | G67: 47 | H67: 0.003 | I67: 1
F68: 41 | G68: 47 | H68: 0.003 | I68: 1
F69: 49 | G69: 54 | H69: 0.0015 | I69: 1
F70: 46 | G70: 39 | H70: 0.003 | I70: 1
... F79: 56 | G79: 57 | H79: 0.0019 | I79: 1

Sheet Result_hydraulic_1
D1: Cost | E1: Qd
A2: (61, 69, 1) | B2: d = 0.2 | C2: z = (0.8,-9.1 ) | D2: 273545.42 | E2: 0.0025
A3: (69, 77, 2) | B3: d = 0.35 | C3: z = (-9.1,-9.15 ) | D3: 794025.99 | E3: 0.0025
A4: (77, 78, 2) | B4: d = 0.38 | C4: z = (-9.15,-9.18 ) | D4: 409972.14 | E4: 0.34
A5: (68, 75, 1) | B5: d = 0.2 | C5: z = (0.9,-8.95 ) | D5: 273545.42 | E5: 0.3245
A6: (75, 77, 2) | B6: d = 0.3 | C6: z = (-8.95,-9.1 ) | D6: 509406.29 | E6: 0.3245
A7: Total computational time: 6.54 seconds
A12: i | B12: j | C12: t | D12: q_ij | E12: cost_ij | F12: new_slope | G12: new_intercept
A13: 44 | B13: 50 | C13: 1 | D13: 0.0025 | E13: 273545.4233247841 | F13: =E13/D13 -> 1.0941817e+08
A14: 50 | B14: 56 | C14: 1 | D14: 0.0025 | E14: 794025.9881751882 | F14: =E14/D14 -> 3.176104e+08
A15: 56 | B15: 57 | C15: 1 | D15: 0.3400000000000002 | E15: 409972.1403986862 | F15: =E15/D15 -> 1205800.4
A16: 49 | B16: 54 | C16: 1 | D16: 0.3245000000000002 | E16: 273545.4233247841 | F16: =E16/D16 -> 842975.11
A17: 54 | B17: 56 | C17: 1 | D17: 0.3245000000000002 | E17: 509406.2895703747 | F17: =E17/D17 -> 1569819.1

Sheet Input_Iter2
A1: i | B1: j | C1: c_ij | D1: a_ij
A2: 4 | B2: 3 | C2: 0.003 | D2: 1
A3: 1 | B3: 2 | C3: 0.003 | D3: 1
A4: 2 | B4: 55 | C4: 0.0038 | D4: 1
A5: 1 | B5: 7 | C5: 0.003 | D5: 1
A6: 19 | B6: 18 | C6: 0.003 | D6: 1
A7: 5 | B7: 8 | C7: 0.003 | D7: 1
A8: 6 | B8: 11 | C8: 0.0027 | D8: 1
A9: 7 | B9: 8 | C9: 0.003 | D9: 1
A10: 8 | B10: 9 | C10: 0.0024 | D10: 1
A11: 9 | B11: 15 | C11: 0.002 | D11: 1
A12: 10 | B12: 11 | C12: 0.003 | D12: 1
A13: 10 | B13: 55 | C13: 0.003 | D13: 1
... A68: 41 | B68: 47 | C68: 0.003 | D68: 1
A69: 49 | B69: 54 | C69: =Result_hydraulic_1!F16 -> 842975.11 | D69: 0
A70: 46 | B70: 39 | C70: 0.003 | D70: 1
A71: 44 | B71: 50 | C71: =Result_hydraulic_1!F13 -> 1.0941817e+08 | D71: 0
A72: 51 | B72: 52 | C72: 0.003 | D72: 1
A73: 52 | B73: 53 | C73: 0.0029 | D73: 1
A74: 53 | B74: 54 | C74: 0.0029 | D74: 1
A75: 54 | B75: 56 | C75: =Result_hydraulic_1!F17 -> 1569819.1 | D75: 0
A76: 55 | B76: 6 | C76: 0.0035 | D76: 1
A77: 55 | B77: 5 | C77: 0.003 | D77: 1
A78: 56 | B78: 50 | C78: =Result_hydraulic_1!F14 -> 3.176104e+08 | D78: 0
A79: 56 | B79: 57 | C79: =Result_hydraulic_1!F15 -> 1205800.4 | D79: 0

Sheet Result_hydraulic_2
A1: i | B1: j | C1: t | D1: q_ij | E1: cost_ij
A2: 4 | B2: 3 | C2: 1 | D2: 0.003 | E2: 345554.3298778656
A3: 3 | B3: 2 | C3: 1 | D3: 0.008 | E3: 452109.7741310441
A4: 2 | B4: 1 | C4: 1 | D4: 0.0079999935 | E4: 532069.5903446816
A5: 1 | B5: 7 | C5: 1 | D5: 0.012999993529793554 | E5: 595012.3612293066
A6: 6 | B6: 11 | C6: 1 | D6: 0.0024999987 | E6: 273545.42424924014
A7: 11 | B7: 17 | C7: 1 | D7: 0.031000001250000624 | E7: 283731.3520424872
A8: 17 | B8: 22 | C8: 1 | D8: 0.037000001 | E8: 283731.35
A9: 22 | B9: 23 | C9: 1 | D9: 0.056750002 | E9: 283731.35
A10: 23 | B10: 35 | C10: 1 | D10: 0.077500002 | E10: 576804.0908589236
A11: 35 | B11: 43 | C11: 1 | D11: 0.10899999937061994 | E11: 726478.3881793582
A12: 43 | B12: 42 | C12: 1 | D12: 0.11575000124859278 | E12: 452294.8606980291
A13: 42 | B13: 41 | C13: 1 | D13: 0.12775000034859205 | E13: 481373.33204124786
A14: 10 | B14: 11 | C14: 1 | D14: 0.0025 | E14: 265688.9934396152
A15: 12 | B15: 11 | C15: 1 | D15: 0.004 | E15: 273545.4251736962
A16: 13 | B16: 7 | C16: 1 | D16: 0.0017499994 | E16: 273545.42424924014
A17: 7 | B17: 8 | C17: 1 | D17: 0.023749992 | E17: 452120.1582583494
A18: 8 | B18: 9 | C18: 1 | D18: 0.042749989 | E18: 683545.9022103148
A19: 9 | B19: 15 | C19: 1 | D19: 0.062499997492942466 | E19: 684935.7754487975
A20: 15 | B20: 20 | C20: 1 | D20: 0.064499997 | E20: 730392.5840763226
A21: 20 | B21: 27 | C21: 1 | D21: 0.12424998816417249 | E21: 730734.6765961621
A22: 27 | B22: 32 | C22: 1 | D22: 0.1332499881641725 | E22: 730734.6765961621
A23: 32 | B23: 40 | C23: 1 | D23: 0.15374998816417249 | E23: 1538839.253996287
A24: 40 | B24: 41 | C24: 1 | D24: 0.1602499881641725 | E24: 817888.1306563157
A25: 41 | B25: 47 | C25: 1 | D25: 0.29399998851276454 | E25: 881000.7406225392
A26: 47 | B26: 52 | C26: 1 | D26: 0.31549999719999794 | E26: 902109.8865210543
A27: 52 | B27: 53 | C27: 1 | D27: 0.3270000000000002 | E27: 942614.21
A28: 53 | B28: 54 | C28: 1 | D28: 0.3270000000000002 | E28: 982729.0209957804
A29: 54 | B29: 56 | C29: 1 | D29: 0.3270000000000002 | E29: 1408553.6415247417
A30: 56 | B30: 57 | C30: 1 | D30: 0.3400000000000002 | E30: 1060750.0482356483
A31: 13 | B31: 18 | C31: 1 | D31: 0.0017499994 | E31: 273545.4233247841
A32: 14 | B32: 8 | C32: 1 | D32: 0.0019999992 | E32: 273545.4233247841
A33: 14 | B33: 19 | C33: 1 | D33: 0.0019999992 | E33: 273545.4233247841
A34: 16 | B34: 21 | C34: 1 | D34: 0.00225 | E34: 265688.9928448103
A35: 21 | B35: 20 | C35: 1 | D35: 0.013 | E35: 273545.4233247841
A36: 26 | B36: 19 | C36: 1 | D36: 0.00049999995 | E36: 273545.4233247841
A37: 26 | B37: 31 | C37: 1 | D37: 0.00049999995 | E37: 265688.9928448103
A38: 28 | B38: 21 | C38: 1 | D38: 0.001 | E38: 273545.4233247841
A39: 21 | B39: 22 | C39: 1 | D39: 0.00325 | E39: 283731.35
A40: 28 | B40: 33 | C40: 1 | D40: 0.003 | E40: 265688.9928448103
...

Sheet Input_Iter3
A1: i | B1: j | C1: c_ij | D1: a_ij
A2: 4 | B2: 3 | C2: 1.1518478e+08 | D2: 0 | F2: =CONCATENATE(A2," ",B2," ",C2," ", D2) -> 4 3 115184776.625955 0
A3: 2 | B3: 1 | C3: 66508753 | D3: 0 | F3: =CONCATENATE(A3," ",B3," ",C3," ", D3) -> 2 1 66508752.5837552 0
A4: 2 | B4: 55 | C4: 0.0038 | D4: 1 | F4: =CONCATENATE(A4," ",B4," ",C4," ", D4) -> 2 55 0.0038 1
A5: 1 | B5: 7 | C5: 45770204 | D5: 0 | F5: =CONCATENATE(A5," ",B5," ",C5," ", D5) -> 1 7 45770204.4132293 0
A6: 18 | B6: 19 | C6: 27384710 | D6: 0 | F6: =CONCATENATE(A6," ",B6," ",C6," ", D6) -> 18 19 27384709.643713 0
A7: 5 | B7: 8 | C7: 0.003 | D7: 1 | F7: =CONCATENATE(A7," ",B7," ",C7," ", D7) -> 5 8 0.003 1
A8: 6 | B8: 11 | C8: 1.0941822e+08 | D8: 0 | F8: =CONCATENATE(A8," ",B8," ",C8," ", D8) -> 6 11 109418224.408836 0
A9: 7 | B9: 8 | C9: 19036645 | D9: 0 | F9: =CONCATENATE(A9," ",B9," ",C9," ", D9) -> 7 8 19036645.0016348 0
A10: 8 | B10: 9 | C10: 15989382 | D10: 0 | F10: =CONCATENATE(A10," ",B10," ",C10," ", D10) -> 8 9 15989381.9453704 0
A11: 9 | B11: 15 | C11: 10958973 | D11: 0 | F11: =CONCATENATE(A11," ",B11," ",C11," ", D11) -> 9 15 10958972.8467772 0
A12: 10 | B12: 11 | C12: 1.062756e+08 | D12: 0 | F12: =CONCATENATE(A12," ",B12," ",C12," ", D12) -> 10 11 106275597.375846 0
A13: 10 | B13: 55 | C13: 0.003 | D13: 1 | F13: =CONCATENATE(A13," ",B13," ",C13," ", D13) -> 10 55 0.003 1
... A79: 56 | B79: 57 | C79: 3119853.1 | D79: 0 | F79: =CONCATENATE(A79," ",B79," ",C79," ", D79) -> 56 57 3119853.08304602 0

Sheet Result_hydraulic_3
A1: i | B1: j | C1: t | D1: q_ij | E1: cost_ij
A2: 49 | B2: 54 | C2: 1 | D2: 0.30150000000000016 | E2: 273545.4233247841 | F2: =E2/D2 -> 907281.67
A3: 54 | B3: 56 | C3: 1 | D3: 0.3270000000000002 | E3: 509406.2895703747 | F3: =E3/D3 -> 1557817.4
A4: 56 | B4: 57 | C4: 1 | D4: 0.3400000000000002 | E4: 390832.57833070896 | F4: =E4/D4 -> 1149507.6
G5: SOLUTION...
G6: 3
G7: Designed Section:
G8: (66, 71, 1) : d = 0.2 , z = (0.9,-8.95 ) cost: 273545.4233247841 Qd:0.30150000000000016
G9: Designed Section:
G10: (71, 73, 2) : d = 0.3 , z = (-8.95,-9.1 ) cost: 509406.2895703747 Qd:0.3270000000000002
G11: Designed Section:
G12: (73, 74, 2) : d = 0.35 , z = (-9.1,-9.15 ) cost: 390832.57833070896 Qd:0.3400000000000002

Sheet Input_Iter4
A1: i | B1: j | C1: c_ij | D1: a_ij
A2: 4 | B2: 3 | C2: 1.1518478e+08 | D2: 0 | F2: =CONCATENATE(A2," ",B2," ",C2," ", D2) -> 4 3 115184776.625955 0
A3: 2 | B3: 1 | C3: 66508753 | D3: 0 | F3: =CONCATENATE(A3," ",B3," ",C3," ", D3) -> 2 1 66508752.5837552 0
A4: 2 | B4: 55 | C4: 0.0038 | D4: 1 | F4: =CONCATENATE(A4," ",B4," ",C4," ", D4) -> 2 55 0.0038 1
A5: 1 | B5: 7 | C5: 45770204 | D5: 0 | F5: =CONCATENATE(A5," ",B5," ",C5," ", D5) -> 1 7 45770204.4132293 0
A6: 18 | B6: 19 | C6: 27384710 | D6: 0 | F6: =CONCATENATE(A6," ",B6," ",C6," ", D6) -> 18 19 27384709.643713 0
A7: 5 | B7: 8 | C7: 0.003 | D7: 1 | F7: =CONCATENATE(A7," ",B7," ",C7," ", D7) -> 5 8 0.003 1
A8: 6 | B8: 11 | C8: 1.0941822e+08 | D8: 0 | F8: =CONCATENATE(A8," ",B8," ",C8," ", D8) -> 6 11 109418224.408836 0
A9: 7 | B9: 8 | C9: 19036645 | D9: 0 | F9: =CONCATENATE(A9," ",B9," ",C9," ", D9) -> 7 8 19036645.0016348 0
A10: 8 | B10: 9 | C10: 15989382 | D10: 0 | F10: =CONCATENATE(A10," ",B10," ",C10," ", D10) -> 8 9 15989381.9453704 0
A11: 9 | B11: 15 | C11: 10958973 | D11: 0 | F11: =CONCATENATE(A11," ",B11," ",C11," ", D11) -> 9 15 10958972.8467772 0
A12: 10 | B12: 11 | C12: 1.062756e+08 | D12: 0 | F12: =CONCATENATE(A12," ",B12," ",C12," ", D12) -> 10 11 106275597.375846 0
A13: 10 | B13: 55 | C13: 0.003 | D13: 1 | F13: =CONCATENATE(A13," ",B13," ",C13," ", D13) -> 10 55 0.003 1
... A79: 56 | B79: 57 | C79: 1149507.6 | D79: 0 | F79: =CONCATENATE(A79," ",B79," ",C79," ", D79) -> 56 57 1149507.58332561 0

Sheet Result_hydraulic_4
A1: i | B1: j | C1: t | D1: q_ij | E1: cost_ij
A2: 39 | B2: 38 | C2: 1 | D2: 0.0005 | E2: 273545.4233247841 | F2: =E2/D2 -> 5.4709085e+08
A3: 38 | B3: 45 | C3: 1 | D3: 0.0035 | E3: 458942.0349649269 | F3: =E3/D3 -> 1.311263e+08
A4: 45 | B4: 51 | C4: 1 | D4: 0.0085 | E4: 509512.62655038806 | F4: =E4/D4 -> 59942662
A5: 51 | B5: 52 | C5: 1 | D5: 0.0115 | E5: 390832.57833070896 | F5: =E5/D5 -> 33985442
A6: 39 | B6: 46 | C6: 1 | D6: 0.0005 | E6: 388343.07807876443 | F6: =E6/D6 -> 7.7668616e+08
A7: 46 | B7: 47 | C7: 1 | D7: 0.0035 | E7: 390684.56 | F7: =E7/D7 -> 1.1162416e+08
A8: 47 | B8: 52 | C8: 1 | D8: 0.014 | E8: 409972.1403986862 | F8: =E8/D8 -> 29283724
A9: 52 | B9: 53 | C9: 1 | D9: 0.025500000000000023 | E9: 422415.88796724565 | F9: =E9/D9 -> 16565329
A10: 53 | B10: 54 | C10: 1 | D10: 0.025500000000000023 | E10: 481278.8893974336 | F10: =E10/D10 -> 18873682
A11: 54 | B11: 56 | C11: 1 | D11: 0.3270000000000002 | E11: 686426.8323669605 | F11: =E11/D11 -> 2099164.6
A12: 56 | B12: 57 | C12: 1 | D12: 0.3400000000000002 | E12: 498255.2465586415 | F12: =E12/D12 -> 1465456.6
A13: 41 | B13: 47 | C13: 1 | D13: 0.0015 | E13: 273545.4233247841 | F13: =E13/D13 -> 1.8236362e+08
A14: 48 | B14: 47 | C14: 1 | D14: 0.002 | E14: 273545.4233247841 | F14: =E14/D14 -> 1.3677271e+08
A15: 49 | B15: 54 | C15: 1 | D15: 0.30150000000000016 | E15: 273545.4233247841 | F15: =E15/D15 -> 907281.67
G23: SOLUTION...
G24: 14
G25: Designed Section:
G26: (52, 49, 1) : d = 0.2 , z = (0.9,-9.0 ) cost: 273545.4233247841 Qd:0.0005
G27: Designed Section:
G28: (49, 61, 2) : d = 0.25 , z = (-9.0,-9.05 ) cost: 458942.0349649269 Qd:0.0035
G29: Designed Section:
G30: (61, 70, 2) : d = 0.3 , z = (-9.05,-9.1 ) cost: 509512.62655038806 Qd:0.0085
G31: Designed Section:
G32: (70, 71, 2) : d = 0.35 , z = (-9.1,-9.15 ) cost: 390832.57833070896 Qd:0.0115
G33: Designed Section:
G34: (53, 62, 1) : d = 0.2 , z = (0.9,-9.1 ) cost: 388343.07807876443 Qd:0.0005
G35: Designed Section:
G36: (62, 63, 2) : d = 0.35 , z = (-9.1,-9.15 ) cost: 390684.557059218 Qd:0.0035
... G55: Total computational time: 15.44 seconds

Sheet Input_Iter5
A1: i | B1: j | C1: c_ij | D1: a_ij
A2: 4 | B2: 3 | C2: 1.1518478e+08 | D2: 0 | F2: =CONCATENATE(A2," ",B2," ",C2," ", D2) -> 4 3 115184776.625955 0
A3: 2 | B3: 1 | C3: 66508753 | D3: 0 | F3: =CONCATENATE(A3," ",B3," ",C3," ", D3) -> 2 1 66508752.5837552 0
A4: 2 | B4: 55 | C4: 0.0038 | D4: 1 | F4: =CONCATENATE(A4," ",B4," ",C4," ", D4) -> 2 55 0.0038 1
A5: 1 | B5: 7 | C5: 45770204 | D5: 0 | F5: =CONCATENATE(A5," ",B5," ",C5," ", D5) -> 1 7 45770204.4132293 0
A6: 18 | B6: 19 | C6: 27384710 | D6: 0 | F6: =CONCATENATE(A6," ",B6," ",C6," ", D6) -> 18 19 27384709.643713 0
A7: 5 | B7: 8 | C7: 0.003 | D7: 1 | F7: =CONCATENATE(A7," ",B7," ",C7," ", D7) -> 5 8 0.003 1
A8: 6 | B8: 11 | C8: 1.0941822e+08 | D8: 0 | F8: =CONCATENATE(A8," ",B8," ",C8," ", D8) -> 6 11 109418224.408836 0
A9: 7 | B9: 8 | C9: 19036645 | D9: 0 | F9: =CONCATENATE(A9," ",B9," ",C9," ", D9) -> 7 8 19036645.0016348 0
A10: 8 | B10: 9 | C10: 15989382 | D10: 0 | F10: =CONCATENATE(A10," ",B10," ",C10," ", D10) -> 8 9 15989381.9453704 0
A11: 9 | B11: 15 | C11: 10958973 | D11: 0 | F11: =CONCATENATE(A11," ",B11," ",C11," ", D11) -> 9 15 10958972.8467772 0
A12: 10 | B12: 11 | C12: 1.062756e+08 | D12: 0 | F12: =CONCATENATE(A12," ",B12," ",C12," ", D12) -> 10 11 106275597.375846 0
A13: 10 | B13: 55 | C13: 0.003 | D13: 1 | F13: =CONCATENATE(A13," ",B13," ",C13," ", D13) -> 10 55 0.003 1
... A18: 13 | B18: 18 | C18: 1.5631173e+08 | D18: 0 | F18: =CONCATENATE(A18," ",B18," ",C18," ", D18) -> 13 18 156311725.180429 0
A19: 14 | B19: 8 | C19: 1.3677277e+08 | D19: 0 | F19: =CONCATENATE(A19," ",B19," ",C19," ", D19) -> 14 8 136772766.371518 0 | H19: `
A20: 14 | B20: 19 | C20: 1.3677277e+08 | D20: 0 | F20: =CONCATENATE(A20," ",B20," ",C20," ", D20) -> 14 19 136772766.371518 0
A21: 15 | B21: 20 | C21: 11323916 | D21: 0 | F21: =CONCATENATE(A21," ",B21," ",C21," ", D21) -> 15 20 11323916.4723416 0
A22: 16 | B22: 10 | C22: 0.003 | D22: 1 | F22: =CONCATENATE(A22," ",B22," ",C22," ", D22) -> 16 10 0.003 1
A23: 19 | B23: 20 | C23: 20421010 | D23: 0 | F23: =CONCATENATE(A23," ",B23," ",C23," ", D23) -> 19 20 20421010.2592298 0
A24: 17 | B24: 22 | C24: 7668414.6 | D24: 0 | F24: =CONCATENATE(A24," ",B24," ",C24," ", D24) -> 17 22 7668414.63123387 0
A25: 25 | B25: 18 | C25: 48124155 | D25: 0 | F25: =CONCATENATE(A25," ",B25," ",C25," ", D25) -> 25 18 48124155.247951 0
A26: 10 | B26: 9 | C26: 0.003 | D26: 1 | F26: =CONCATENATE(A26," ",B26," ",C26," ", D26) -> 10 9 0.003 1
A27: 26 | B27: 19 | C27: 5.470909e+08 | D27: 0 | F27: =CONCATENATE(A27," ",B27," ",C27," ", D27) -> 26 19 547090901.358664 0
A28: 20 | B28: 27 | C28: 5881165 | D28: 0 | F28: =CONCATENATE(A28," ",B28," ",C28," ", D28) -> 20 27 5881164.95939329 0
A29: 21 | B29: 20 | C29: 21041956 | D29: 0 | F29: =CONCATENATE(A29," ",B29," ",C29," ", D29) -> 21 20 21041955.640368 0
A30: 28 | B30: 21 | C30: 2.7354542e+08 | D30: 0 | F30: =CONCATENATE(A30," ",B30," ",C30," ", D30) -> 28 21 273545423.324784 0
A31: 22 | B31: 23 | C31: 4999671.2 | D31: 0 | F31: =CONCATENATE(A31," ",B31," ",C31," ", D31) -> 22 23 4999671.23245342 0
... A79: 56 | B79: 57 | C79: 1465456.6 | D79: 0 | F79: =CONCATENATE(A79," ",B79," ",C79," ", D79) -> 56 57 1465456.60752542 0

Sheet Result_hydraulic_5
A1: i | B1: j | C1: t | D1: q_ij | E1: cost_ij
A2: 49 | B2: 54 | C2: 1 | D2: 0.3047499999987196 | E2: 273545.4233247841
A3: 54 | B3: 56 | C3: 1 | D3: 0.3270000000000002 | E3: 509406.2895703747
A4: 56 | B4: 57 | C4: 1 | D4: 0.3400000000000002 | E4: 390832.57833070896
I21: SOLUTION...
I22: 3
I23: Designed Section:
I24: (63, 67, 1) : d = 0.2 , z = (0.9,-8.95 ) cost: 273545.4233247841 Qd:0.3047499999987196
I25: Designed Section:
I26: (67, 69, 2) : d = 0.3 , z = (-8.95,-9.1 ) cost: 509406.2895703747 Qd:0.3270000000000002
I27: Designed Section:
I28: (69, 70, 2) : d = 0.35 , z = (-9.1,-9.15 ) cost: 390832.57833070896 Qd:0.3400000000000002

Sheet Input_Iter6
A1: i | B1: j | C1: c_ij | D1: a_ij
A2: 4 | B2: 3 | C2: 1.1518478e+08 | D2: 0 | F2: =CONCATENATE(A2," ",B2," ",C2," ", D2) -> 4 3 115184776.6 0
A3: 2 | B3: 1 | C3: 66508753 | D3: 0 | F3: =CONCATENATE(A3," ",B3," ",C3," ", D3) -> 2 1 66508752.58 0
A4: 2 | B4: 55 | C4: 0.0038 | D4: 1 | F4: =CONCATENATE(A4," ",B4," ",C4," ", D4) -> 2 55 0.0038 1
A5: 1 | B5: 7 | C5: 45770204 | D5: 0 | F5: =CONCATENATE(A5," ",B5," ",C5," ", D5) -> 1 7 45770204.41 0
A6: 18 | B6: 19 | C6: 27384710 | D6: 0 | F6: =CONCATENATE(A6," ",B6," ",C6," ", D6) -> 18 19 27384709.64 0
A7: 5 | B7: 8 | C7: 0.003 | D7: 1 | F7: =CONCATENATE(A7," ",B7," ",C7," ", D7) -> 5 8 0.003 1
A8: 6 | B8: 11 | C8: 1.0941822e+08 | D8: 0 | F8: =CONCATENATE(A8," ",B8," ",C8," ", D8) -> 6 11 109418224.4 0
A9: 7 | B9: 8 | C9: 19036645 | D9: 0 | F9: =CONCATENATE(A9," ",B9," ",C9," ", D9) -> 7 8 19036645 0
A10: 8 | B10: 9 | C10: 15989382 | D10: 0 | F10: =CONCATENATE(A10," ",B10," ",C10," ", D10) -> 8 9 15989381.95 0
A11: 9 | B11: 15 | C11: 10958973 | D11: 0 | F11: =CONCATENATE(A11," ",B11," ",C11," ", D11) -> 9 15 10958972.85 0
A12: 10 | B12: 11 | C12: 1.062756e+08 | D12: 0 | F12: =CONCATENATE(A12," ",B12," ",C12," ", D12) -> 10 11 106275597.4 0
A13: 10 | B13: 55 | C13: 0.003 | D13: 1 | F13: =CONCATENATE(A13," ",B13," ",C13," ", D13) -> 10 55 0.003 1
... A79: 56 | B79: 57 | C79: 1149507.6 | D79: 0 | F79: =CONCATENATE(A79," ",B79," ",C79," ", D79) -> 56 57 1149507.583 0

Sheet Result_hydraulic_6
A1: i | B1: j | C1: t | D1: q_ij | E1: cost_ij
A2: 49 | B2: 54 | C2: 1 | D2: 0.3047500000000002 | E2: 273545.4233247841
A3: 54 | B3: 56 | C3: 1 | D3: 0.3270000000000002 | E3: 509406.2895703747
A4: 56 | B4: 57 | C4: 1 | D4: 0.3400000000000002 | E4: 390832.57833070896
I18: SOLUTION...
I19: 3
I20: Designed Section:
I21: (65, 69, 1) : d = 0.2 , z = (0.9,-8.95 ) cost: 273545.4233247841 Qd:0.3047500000000002
I22: Designed Section:
I23: (69, 71, 2) : d = 0.3 , z = (-8.95,-9.1 ) cost: 509406.2895703747 Qd:0.3270000000000002
I24: Designed Section:
I25: (71, 72, 2) : d = 0.35 , z = (-9.1,-9.15 ) cost: 390832.57833070896 Qd:0.3400000000000002

Sheet Input_Iter7
A1: i | B1: j | C1: c_ij | D1: a_ij
A2: 4 | B2: 3 | C2: 1.1518478e+08 | D2: 0 | F2: =CONCATENATE(A2," ",B2," ",C2," ", D2) -> 4 3 115184776.6 0
A3: 2 | B3: 1 | C3: 66508753 | D3: 0 | F3: =CONCATENATE(A3," ",B3," ",C3," ", D3) -> 2 1 66508752.58 0
A4: 2 | B4: 55 | C4: 0.0038 | D4: 1 | F4: =CONCATENATE(A4," ",B4," ",C4," ", D4) -> 2 55 0.0038 1
A5: 1 | B5: 7 | C5: 45770204 | D5: 0 | F5: =CONCATENATE(A5," ",B5," ",C5," ", D5) -> 1 7 45770204.41 0
A6: 18 | B6: 19 | C6: 27384710 | D6: 0 | F6: =CONCATENATE(A6," ",B6," ",C6," ", D6) -> 18 19 27384709.64 0
A7: 5 | B7: 8 | C7: 0.003 | D7: 1 | F7: =CONCATENATE(A7," ",B7," ",C7," ", D7) -> 5 8 0.003 1
A8: 6 | B8: 11 | C8: 1.0941822e+08 | D8: 0 | F8: =CONCATENATE(A8," ",B8," ",C8," ", D8) -> 6 11 109418224.4 0
A9: 7 | B9: 8 | C9: 19036645 | D9: 0 | F9: =CONCATENATE(A9," ",B9," ",C9," ", D9) -> 7 8 19036645 0
A10: 8 | B10: 9 | C10: 15989382 | D10: 0 | F10: =CONCATENATE(A10," ",B10," ",C10," ", D10) -> 8 9 15989381.95 0
A11: 9 | B11: 15 | C11: 10958973 | D11: 0 | F11: =CONCATENATE(A11," ",B11," ",C11," ", D11) -> 9 15 10958972.85 0
A12: 10 | B12: 11 | C12: 1.062756e+08 | D12: 0 | F12: =CONCATENATE(A12," ",B12," ",C12," ", D12) -> 10 11 106275597.4 0
A13: 10 | B13: 55 | C13: 0.003 | D13: 1 | F13: =CONCATENATE(A13," ",B13," ",C13," ", D13) -> 10 55 0.003 1
... A79: 56 | B79: 57 | C79: 1149507.6 | D79: 0 | F79: =CONCATENATE(A79," ",B79," ",C79," ", D79) -> 56 57 1149507.58332561 0

Sheet Result_hydraulic_7
